<?xml version="1.0" ?>
<robot name="robot">

    <link name="base_link">
        <visual>
            <origin xyz=" 0 0 0" rpy="0 0 0" />
            <geometry>
                <box size="1 0.5 0.3"/>
            </geometry>
            <material name="yellow">
                <color rgba="1 0.4 0 1"/>
            </material>
        </visual>
    </link>

    <joint name="front_left_wheel_joint" type="continuous">
        <origin xyz="0.35 0.25 -0.15" rpy="0 0 0"/>
        <parent link="base_link"/>
        <child link="front_left_wheel_link"/>
        <axis xyz="0 1 0"/>
    </joint>

    <link name="front_left_wheel_link">
        <visual>
            <origin xyz="0 0 0" rpy="1.5707 0 0" />
            <geometry>
                <cylinder radius="0.12" length = "0.025"/>
            </geometry>
            <material name="white">
                <color rgba="1 1 1 0.9"/>
            </material>
        </visual>
    </link>

    <joint name="front_right_wheel_joint" type="continuous">
        <origin xyz="0.35 -0.25 -0.15" rpy="0 0 0"/>
        <parent link="base_link"/>
        <child link="front_right_wheel_link"/>
        <axis xyz="0 1 0"/>
    </joint>

    <link name="front_right_wheel_link">
        <visual>
            <origin xyz="0 0 0" rpy="1.5707 0 0" />
            <geometry>
                <cylinder radius="0.12" length = "0.025"/>
            </geometry>
            <material name="white">
                <color rgba="1 1 1 0.9"/>
            </material>
        </visual>
    </link>

    <joint name="back_left_wheel_joint" type="continuous">
        <origin xyz="-0.35 0.25 -0.15" rpy="0 0 0"/>
        <parent link="base_link"/>
        <child link="back_left_wheel_link"/>
        <axis xyz="0 1 0"/>
    </joint>

    <link name="back_left_wheel_link">
        <visual>
            <origin xyz="0 0 0" rpy="1.5707 0 0" />
            <geometry>
                <cylinder radius="0.12" length = "0.025"/>
            </geometry>
            <material name="white">
                <color rgba="1 1 1 0.9"/>
            </material>
        </visual>
    </link>

    <joint name="back_right_wheel_joint" type="continuous">
        <origin xyz="-0.35 -0.25 -0.15" rpy="0 0 0"/>
        <parent link="base_link"/>
        <child link="back_right_wheel_link"/>
        <axis xyz="0 1 0"/>
    </joint>

    <link name="back_right_wheel_link">
        <visual>
            <origin xyz="0 0 0" rpy="1.5707 0 0" />
            <geometry>
                <cylinder radius="0.12" length = "0.025"/>
            </geometry>
            <material name="white">
                <color rgba="1 1 1 0.9"/>
            </material>
        </visual>
    </link>

    <link name="kinect_link">
        <visual>
            <origin xyz="0 0 0" rpy="0 0 1.5708"/>
            <geometry>
                <mesh filename="package://robot_description/meshes/kinect.dae" />
            </geometry>
        </visual>
    </link>

    <joint name="kinect_joint" type="fixed">
        <origin xyz="0.45 0 0.17" rpy="0 0 0"/>
        <parent link="base_link"/>
        <child link="kinect_link"/>
    </joint>

    <link name="laser_link">
	<visual>
		<origin xyz=" 0 0 0 " rpy="0 0 0" />
		<geometry>
			<cylinder length="0.10" radius="0.10"/>
		</geometry>
		<material name="black"/>
	</visual>
    </link>

    <joint name="laser_joint" type="fixed">
        <origin xyz="0 0 0.20" rpy="0 0 0"/>
        <parent link="base_link"/>
        <child link="laser_link"/>
    </joint>

</robot>
